<?xml version="1.0" ?>
<!-- This URDF was automatically created by SolidWorks to URDF Exporter! Originally created by Stephen Brawner (brawner@gmail.com) 
     Commit Version: 1.6.0-4-g7f85cfe  Build Version: 1.6.7995.38578
     For more information, please see http://wiki.ros.org/sw_urdf_exporter -->
<robot
  name="cyber_shopper" xmlns:xacro="http://ros.org/wiki/xacro">
  #Add colors in gazebo
  <xacro:macro name="body_color">
    <visual>
    <material>
        <ambient>0.5 0.5 0.5 1.0</ambient>
        <diffuse>0.5 0.5 0.5 1.0</diffuse>
        <specular>0.7 0.7 0.7 1.0</specular>
        <emissive>0 0 0 1.0</emissive>
    </material>
    </visual>
  </xacro:macro>
<gazebo reference="base_link">
    <xacro:body_color />
</gazebo>
  <xacro:macro name="fr_wheel_color">
    <visual>
    <material>
        <ambient>0 0 0 1.0</ambient>
        <diffuse>0 0 0 1.0</diffuse>
        <specular>0 0 0 1.0</specular>
        <emissive>0 0 0 1.0</emissive>
    </material>
    </visual>
  </xacro:macro>
<gazebo reference="front-right-wheel">
    <xacro:fr_wheel_color/>
</gazebo>
<xacro:macro name="fl_wheel_color">
    <visual>
    <material>
        <ambient>0 0 0 1.0</ambient>
        <diffuse>0 0 0 1.0</diffuse>
        <specular>0 0 0 1.0</specular>
        <emissive>0 0 0 1.0</emissive>
    </material>
    </visual>
  </xacro:macro>
<gazebo reference="front-left-wheel">
    <xacro:fl_wheel_color/>
</gazebo>
<xacro:macro name="rr_wheel_color">
    <visual>
    <material>
        <ambient>0 0 0 1.0</ambient>
        <diffuse>0 0 0 1.0</diffuse>
        <specular>0 0 0 1.0</specular>
        <emissive>0 0 0 1.0</emissive>
    </material>
    </visual>
  </xacro:macro>
<gazebo reference="rear-right-wheel">
    <xacro:rr_wheel_color/>
</gazebo>
<xacro:macro name="rl_wheel_color">
    <visual>
    <material>
        <ambient>0 0 0 1.0</ambient>
        <diffuse>0 0 0 1.0</diffuse>
        <specular>0 0 0 1.0</specular>
        <emissive>0 0 0 1.0</emissive>
    </material>
    </visual>
  </xacro:macro>
<gazebo reference="rear-left-wheel">
    <xacro:rl_wheel_color/>
</gazebo>
<xacro:macro name="Lidar">
<visual>
    <material>
        <ambient>0 0 0 1.0</ambient>
        <diffuse>0 0 0 1.0</diffuse>
        <specular>0 0 0 1.0</specular>
        <emissive>0 0 0 1.0</emissive>
    </material>
    </visual>
  </xacro:macro>
<gazebo reference="Lidar">
    <xacro:Lidar/>
</gazebo>
  <xacro:macro name="righthinge">
    <visual>
    <material>
        <ambient>0.8 0.558823529411765 0.1 1</ambient>
        <diffuse>0.8 0.558823529411765 0.1 1</diffuse>
        <specular>0.1 0.1 0.1 1</specular>
        <emissive>0 0 0 0</emissive>
    </material>
    </visual>
</xacro:macro>
<gazebo reference="front-right-hinge">
    <xacro:righthinge />
</gazebo>
  <xacro:macro name="left-hinge">
    <visual>
    <material>
        <ambient>0.8 0.558823529411765 0.1 1</ambient>
        <diffuse>0.8 0.558823529411765 0.1 1</diffuse>
        <specular>0.1 0.1 0.1 1</specular>
        <emissive>0 0 0 0</emissive>
    </material>
    </visual>
</xacro:macro>
<gazebo reference="front-left-hinge">
    <xacro:left-hinge />
</gazebo>
#add this before base_link
  
  
  <link name="dummy_link"></link>
  <link
    name="base_link">
    <inertial>
      <origin
        xyz="0.00513649810212103 9.03758425849811E-10 0.0606164652705573"
        rpy="0 0 0" />
      <mass
        value="5" />
      <inertia
        ixx="1.22050289180843"
        ixy="-1.52624899021945E-08"
        ixz="-0.0908849181337663"
        iyy="3.18537569093476"
        iyz="-1.58588484113967E-10"
        izz="3.95556719098638" />
    </inertial>
    <visual>
      <origin
        xyz="0 0 0"
        rpy="0 0 0" />
      <geometry>
        <mesh
          filename="package://cyber_shopper/meshes/base_link.STL" />
      </geometry>
      <material
        name="">
        <color
          rgba="0.752941176470588 0.752941176470588 0.752941176470588 1" />
      </material>
    </visual>
    <collision>
      <origin
        xyz="0 0 0"
        rpy="0 0 0" />
      <geometry>
        <mesh
          filename="package://cyber_shopper/meshes/base_link.STL" />
      </geometry>
    </collision>
  </link>
  #Add this AFTER BASE LINK
  <joint name="dummy_joint" type="fixed">
    <origin rpy="0 0 0" xyz="0 0 0" />
    <parent link="dummy_link"/>
    <child link="base_link"/>
</joint>
  <link
    name="front-left-hinge">
    <inertial>
      <origin
        xyz="5.55111512312578E-17 5.55111512312578E-17 -0.118799628145585"
        rpy="0 0 0" />
      <mass
        value="0.633612488698204" />
      <inertia
        ixx="0.00421598497152854"
        ixy="2.499711540899E-05"
        ixz="1.39348290409888E-18"
        iyy="0.00246011467135765"
        iyz="-2.18519923436717E-19"
        izz="0.00202629416547586" />
    </inertial>
    <visual>
      <origin
        xyz="0 0 0"
        rpy="0 0 0" />
      <geometry>
        <mesh
          filename="package://cyber_shopper/meshes/front-left-hinge.STL" />
      </geometry>
      <material
        name="">
        <color
          rgba="1 1 0 1" />
      </material>
    </visual>
    <collision>
      <origin
        xyz="0 0 0"
        rpy="0 0 0" />
      <geometry>
        <mesh
          filename="package://cyber_shopper/meshes/front-left-hinge.STL" />
      </geometry>
    </collision>
  </link>
  <joint
    name="fl-hinge"
    type="revolute">
    <origin
      xyz="0.254 0.1397 0.0608000000000001"
      rpy="0 0 0" />
    <parent
      link="base_link" />
    <child
      link="front-left-hinge" />
    <axis
      xyz="0 0 -1" />
    <limit
      lower="-1"
      upper="1"
      effort="0"
      velocity="0" />
  </joint>
  <link
    name="front-left-wheel">
    <inertial>
      <origin
        xyz="-0.0102182858248703 1.38777878078145E-16 0.0367041773481068"
        rpy="0 0 0" />
      <mass
        value="2.43249992415545" />
      <inertia
        ixx="0.00755355776923952"
        ixy="1.88640504073853E-18"
        ixz="7.39771592248954E-05"
        iyy="0.00755250482076537"
        iyz="1.95246869510358E-18"
        izz="0.0127499292164544" />
    </inertial>
    <visual>
      <origin
        xyz="0 0 0"
        rpy="0 0 0" />
      <geometry>
        <mesh
          filename="package://cyber_shopper/meshes/front-left-wheel.STL" />
      </geometry>
      <material
        name="">
        <color
          rgba="0 0 0 1" />
      </material>
    </visual>
    <collision>
      <origin
        xyz="0 0 0"
        rpy="0 0 0" />
      <geometry>
        <mesh
          filename="package://cyber_shopper/meshes/front-left-wheel.STL" />
      </geometry>
    </collision>
  </link>
  <joint
    name="fl-wheel"
    type="continuous">
    <origin
      xyz="-0.0102182858248701 -0.0367041773481067 -0.2005"
      rpy="1.5707963267949 0 -3.14159265358979" />
    <parent
      link="front-left-hinge" />
    <child
      link="front-left-wheel" />
    <axis
      xyz="-0.0142319851525261 0 -0.999898720170507" />
  </joint>
  <link
    name="front-right-hinge">
    <inertial>
      <origin
        xyz="-5.55111512312578E-17 0 -0.118799628145585"
        rpy="0 0 0" />
      <mass
        value="0.633612488698205" />
      <inertia
        ixx="0.00421634076613872"
        ixy="3.80852095203233E-19"
        ixz="-1.06209927949746E-21"
        iyy="0.00245975887674748"
        iyz="-1.06259299540453E-18"
        izz="0.00202629416547586" />
    </inertial>
    <visual>
      <origin
        xyz="0 0 0"
        rpy="0 0 0" />
      <geometry>
        <mesh
          filename="package://cyber_shopper/meshes/front-right-hinge.STL" />
      </geometry>
      <material
        name="">
        <color
          rgba="1 1 0 1" />
      </material>
    </visual>
    <collision>
      <origin
        xyz="0 0 0"
        rpy="0 0 0" />
      <geometry>
        <mesh
          filename="package://cyber_shopper/meshes/front-right-hinge.STL" />
      </geometry>
    </collision>
  </link>
  <joint
    name="fr-hinge"
    type="revolute">
    <origin
      xyz="0.254 -0.1397 0.0608"
      rpy="0 0 0" />
    <parent
      link="base_link" />
    <child
      link="front-right-hinge" />
    <axis
      xyz="0 0 -1" />
    <limit
      lower="-1"
      upper="1"
      effort="0"
      velocity="0" />
  </joint>
  <link
    name="front-right-wheel">
    <inertial>
      <origin
        xyz="-5.55111512312578E-17 2.77555756156289E-17 -0.0381"
        rpy="0 0 0" />
      <mass
        value="2.43249992415545" />
      <inertia
        ixx="0.00755250482076537"
        ixy="6.00508507818468E-19"
        ixz="8.35496005193151E-19"
        iyy="0.00755250482076537"
        iyz="-3.98615026528919E-18"
        izz="0.0127509821649285" />
    </inertial>
    <visual>
      <origin
        xyz="0 0 0"
        rpy="0 0 0" />
      <geometry>
        <mesh
          filename="package://cyber_shopper/meshes/front-right-wheel.STL" />
      </geometry>
      <material
        name="">
        <color
          rgba="0 0 0 1" />
      </material>
    </visual>
    <collision>
      <origin
        xyz="0 0 0"
        rpy="0 0 0" />
      <geometry>
        <mesh
          filename="package://cyber_shopper/meshes/front-right-wheel.STL" />
      </geometry>
    </collision>
  </link>
  <joint
    name="fr-wheel"
    type="continuous">
    <origin
      xyz="0 -0.0381 -0.2005"
      rpy="1.5707963267949 0 0" />
    <parent
      link="front-right-hinge" />
    <child
      link="front-right-wheel" />
    <axis
      xyz="0 0 -1" />
  </joint>
  <link
    name="rear-left-wheel">
    <inertial>
      <origin
        xyz="0 0 -0.0381"
        rpy="0 0 0" />
      <mass
        value="2.43249992415545" />
      <inertia
        ixx="0.00755250482076536"
        ixy="-8.23812994843201E-19"
        ixz="-1.50602458021814E-19"
        iyy="0.00755250482076536"
        iyz="2.88296133927474E-19"
        izz="0.0127509821649285" />
    </inertial>
    <visual>
      <origin
        xyz="0 0 0"
        rpy="0 0 0" />
      <geometry>
        <mesh
          filename="package://cyber_shopper/meshes/rear-left-wheel.STL" />
      </geometry>
      <material
        name="">
        <color
          rgba="0 0 0 1" />
      </material>
    </visual>
    <collision>
      <origin
        xyz="0 0 0"
        rpy="0 0 0" />
      <geometry>
        <mesh
          filename="package://cyber_shopper/meshes/rear-left-wheel.STL" />
      </geometry>
    </collision>
  </link>
  <joint
    name="rl-wheel"
    type="continuous">
    <origin
      xyz="-0.254 0.1778 -0.1397"
      rpy="1.5707963267949 0 3.14159265358979" />
    <parent
      link="base_link" />
    <child
      link="rear-left-wheel" />
    <axis
      xyz="0 0 -1" />
  </joint>
  <link
    name="rear-right-wheel">
    <inertial>
      <origin
        xyz="0 0 -0.0381"
        rpy="0 0 0" />
      <mass
        value="2.43249992415545" />
      <inertia
        ixx="0.00755250482076537"
        ixy="1.16151947225978E-18"
        ixz="3.90126123152596E-19"
        iyy="0.00755250482076537"
        iyz="7.17453761935092E-19"
        izz="0.0127509821649285" />
    </inertial>
    <visual>
      <origin
        xyz="0 0 0"
        rpy="0 0 0" />
      <geometry>
        <mesh
          filename="package://cyber_shopper/meshes/rear-right-wheel.STL" />
      </geometry>
      <material
        name="">
        <color
          rgba="0 0 0 1" />
      </material>
    </visual>
    <collision>
      <origin
        xyz="0 0 0"
        rpy="0 0 0" />
      <geometry>
        <mesh
          filename="package://cyber_shopper/meshes/rear-right-wheel.STL" />
      </geometry>
    </collision>
  </link>
  <joint
    name="rr-wheel"
    type="continuous">
    <origin
      xyz="-0.254 -0.1778 -0.1397"
      rpy="1.5707963267949 0 0" />
    <parent
      link="base_link" />
    <child
      link="rear-right-wheel" />
    <axis
      xyz="0 0 -1" />
  </joint>
  <link
    name="Lidar">
    <inertial>
      <origin
        xyz="5.55111512312578E-17 -1.60727870924178E-18 -0.0127"
        rpy="0 0 0" />
      <mass
        value="0.0128703699690764" />
      <inertia
        ixx="1.21091948384887E-06"
        ixy="-5.87747175411144E-39"
        ixz="4.01153705072005E-39"
        iyy="1.21091948384887E-06"
        iyz="-7.78263594347942E-38"
        izz="1.03793098615617E-06" />
    </inertial>
    <visual>
      <origin
        xyz="0 0 0"
        rpy="0 0 0" />
      <geometry>
        <mesh
          filename="package://cyber_shopper/meshes/Lidar.STL" />
      </geometry>
      <material
        name="">
        <color
          rgba="0 0 0 1" />
      </material>
    </visual>
    <collision>
      <origin
        xyz="0 0 0"
        rpy="0 0 0" />
      <geometry>
        <mesh
          filename="package://cyber_shopper/meshes/Lidar.STL" />
      </geometry>
    </collision>
  </link>
  <joint
    name="laser"
    type="fixed">
    <origin
      xyz="0.45 0 0.2262"
      rpy="0 0 0" />
    <parent
      link="base_link" />
    <child
      link="Lidar" />
    <axis
      xyz="0 0 0" />
  </joint>
  <link
    name="ur5_base_link">
    <inertial>
      <origin
        xyz="-0.000370140905738653 -0.000370700027328298 -0.0137144183679095"
        rpy="0 0 0" />
      <mass
        value="25" />
      <inertia
        ixx="0.000596920259538839"
        ixy="1.75028239429301E-05"
        ixz="1.52109693546543E-06"
        iyy="0.000596946107913878"
        iyz="1.51744540433612E-06"
        izz="0.00105971155653447" />
    </inertial>
    <visual>
      <origin
        xyz="0 0 0"
        rpy="0 0 0" />
      <geometry>
        <mesh
          filename="package://cyber_shopper/meshes/ur5_base_link.STL" />
      </geometry>
      <material
        name="">
        <color
          rgba="0.752941176470588 0.752941176470588 0.752941176470588 1" />
      </material>
    </visual>
    <collision>
      <origin
        xyz="0 0 0"
        rpy="0 0 0" />
      <geometry>
        <mesh
          filename="package://cyber_shopper/meshes/ur5_base_link.STL" />
      </geometry>
    </collision>
  </link>
  <joint
    name="ur5_base_joint"
    type="fixed">
    <origin
      xyz="0 0 0.31027"
      rpy="0 0 3.1416" />
    <parent
      link="base_link" />
    <child
      link="ur5_base_link" />
    <axis
      xyz="0 0 0" />
  </joint>
  <link
    name="ur5_shoulder_pan_link">
    <inertial>
      <origin
        xyz="6.44225963477137E-06 -0.0165820948532893 0.0588582173084062"
        rpy="0 0 0" />
      <mass
        value="0.5" />
      <inertia
        ixx="0.00260530955829497"
        ixy="4.49007348784211E-07"
        ixz="-1.3128013097067E-07"
        iyy="0.00252490488615463"
        iyz="0.000317687897359079"
        izz="0.00282675535060953" />
    </inertial>
    <visual>
      <origin
        xyz="0 0 0"
        rpy="0 0 0" />
      <geometry>
        <mesh
          filename="package://cyber_shopper/meshes/ur5_shoulder_pan_link.STL" />
      </geometry>
      <material
        name="">
        <color
          rgba="0.752941176470588 0.752941176470588 0.752941176470588 1" />
      </material>
    </visual>
    <collision>
      <origin
        xyz="0 0 0"
        rpy="0 0 0" />
      <geometry>
        <mesh
          filename="package://cyber_shopper/meshes/ur5_shoulder_pan_link.STL" />
      </geometry>
    </collision>
  </link>
  <joint
    name="ur5_shoulder_pan_joint"
    type="revolute">
    <origin
      xyz="0 0 0"
      rpy="0 0 0" />
    <parent
      link="ur5_base_link" />
    <child
      link="ur5_shoulder_pan_link" />
    <axis
      xyz="0 0 1" />
    <limit
      lower="-6.28"
      upper="6.28"
      effort="0"
      velocity="0" />
  </joint>
  <link
    name="ur5_shoulder_lift_link">
    <inertial>
      <origin
        xyz="-0.216473407706909 8.73631774145345E-08 -0.0579652222649089"
        rpy="0 0 0" />
      <mass
        value="0.05" />
      <inertia
        ixx="0.00634098535462066"
        ixy="9.00061089919182E-07"
        ixz="9.18905587792872E-12"
        iyy="0.0212957862682851"
        iyz="2.25716232231305E-07"
        izz="0.0218176174727625" />
    </inertial>
    <visual>
      <origin
        xyz="0 0 0"
        rpy="0 0 0" />
      <geometry>
        <mesh
          filename="package://cyber_shopper/meshes/ur5_shoulder_lift_link.STL" />
      </geometry>
      <material
        name="">
        <color
          rgba="0.752941176470588 0.752941176470588 0.752941176470588 1" />
      </material>
    </visual>
    <collision>
      <origin
        xyz="0 0 0"
        rpy="0 0 0" />
      <geometry>
        <mesh
          filename="package://cyber_shopper/meshes/ur5_shoulder_lift_link.STL" />
      </geometry>
    </collision>
  </link>
  <joint
    name="ur5_shoulder_lift_joint"
    type="revolute">
    <origin
      xyz="0 -0.0753 0.0597"
      rpy="1.5708 0 3.1416" />
    <parent
      link="ur5_shoulder_pan_link" />
    <child
      link="ur5_shoulder_lift_link" />
    <axis
      xyz="0 0 -1" />
    <limit
      lower="-6.28"
      upper="6.28"
      effort="0"
      velocity="0" />
  </joint>
  <link
    name="ur5_elbow_link">
    <inertial>
      <origin
        xyz="-0.173301022760315 -2.60974452209739E-06 0.0478359529374315"
        rpy="0 0 0" />
      <mass
        value="0.05" />
      <inertia
        ixx="0.00223825240633508"
        ixy="4.20732100925583E-07"
        ixz="0.000112982508969357"
        iyy="0.0116519639039196"
        iyz="2.68874458165397E-07"
        izz="0.0118071385480294" />
    </inertial>
    <visual>
      <origin
        xyz="0 0 0"
        rpy="0 0 0" />
      <geometry>
        <mesh
          filename="package://cyber_shopper/meshes/ur5_elbow_link.STL" />
      </geometry>
      <material
        name="">
        <color
          rgba="0.752941176470588 0.752941176470588 0.752941176470588 1" />
      </material>
    </visual>
    <collision>
      <origin
        xyz="0 0 0"
        rpy="0 0 0" />
      <geometry>
        <mesh
          filename="package://cyber_shopper/meshes/ur5_elbow_link.STL" />
      </geometry>
    </collision>
  </link>
  <joint
    name="ur5_elbow_joint"
    type="revolute">
    <origin
      xyz="-0.425 0 0.0067"
      rpy="0 0 0" />
    <parent
      link="ur5_shoulder_lift_link" />
    <child
      link="ur5_elbow_link" />
    <axis
      xyz="0 0 -1" />
    <limit
      lower="-6.28"
      upper="6.28"
      effort="0"
      velocity="0" />
  </joint>
  <link
    name="ur5_wrist1_link">
    <inertial>
      <origin
        xyz="1.27924868670304E-05 0.00392699673802965 0.0420455562939766"
        rpy="0 0 0" />
      <mass
        value="0.05" />
      <inertia
        ixx="0.000383780512007027"
        ixy="-2.85578045074219E-07"
        ixz="4.073433547919E-07"
        iyy="0.000410803197024199"
        iyz="4.26540508034186E-05"
        izz="0.000364692071402362" />
    </inertial>
    <visual>
      <origin
        xyz="0 0 0"
        rpy="0 0 0" />
      <geometry>
        <mesh
          filename="package://cyber_shopper/meshes/ur5_wrist1_link.STL" />
      </geometry>
      <material
        name="">
        <color
          rgba="0.752941176470588 0.752941176470588 0.752941176470588 1" />
      </material>
    </visual>
    <collision>
      <origin
        xyz="0 0 0"
        rpy="0 0 0" />
      <geometry>
        <mesh
          filename="package://cyber_shopper/meshes/ur5_wrist1_link.STL" />
      </geometry>
    </collision>
  </link>
  <joint
    name="ur5_wrist1_joint"
    type="revolute">
    <origin
      xyz="-0.39225 0 0.012"
      rpy="-3.1416 0 3.1416" />
    <parent
      link="ur5_elbow_link" />
    <child
      link="ur5_wrist1_link" />
    <axis
      xyz="0 0 1" />
    <limit
      lower="-6.28"
      upper="6.28"
      effort="0"
      velocity="0" />
  </joint>
  <link
    name="ur5_wrist2_link">
    <inertial>
      <origin
        xyz="1.26178590126313E-05 0.00392728594858459 0.0420455562519142"
        rpy="0 0 0" />
      <mass
        value="0.05" />
      <inertia
        ixx="0.000383781445683526"
        ixy="-2.86688310008331E-07"
        ixz="4.08570475517189E-07"
        iyy="0.000410802266717943"
        iyz="4.26519917545766E-05"
        izz="0.000364692071999355" />
    </inertial>
    <visual>
      <origin
        xyz="0 0 0"
        rpy="0 0 0" />
      <geometry>
        <mesh
          filename="package://cyber_shopper/meshes/ur5_wrist2_link.STL" />
      </geometry>
      <material
        name="">
        <color
          rgba="0.752941176470588 0.752941176470588 0.752941176470588 1" />
      </material>
    </visual>
    <collision>
      <origin
        xyz="0 0 0"
        rpy="0 0 0" />
      <geometry>
        <mesh
          filename="package://cyber_shopper/meshes/ur5_wrist2_link.STL" />
      </geometry>
    </collision>
  </link>
  <joint
    name="ur5_wrist2_joint"
    type="revolute">
    <origin
      xyz="0 -0.04155 0.05337"
      rpy="-1.5708 0 3.1416" />
    <parent
      link="ur5_wrist1_link" />
    <child
      link="ur5_wrist2_link" />
    <axis
      xyz="0 0 1" />
    <limit
      lower="-6.28"
      upper="6.28"
      effort="0"
      velocity="0" />
  </joint>
  <link
    name="ur5_wrist3_link">
    <inertial>
      <origin
        xyz="-0.000158856687767939 0.000236158985497781 -0.0219433520297092"
        rpy="0 0 0" />
      <mass
        value="0.05" />
      <inertia
        ixx="6.82785561583494E-05"
        ixy="-3.2401095333924E-07"
        ixz="-5.8937239161678E-08"
        iyy="6.85415552960153E-05"
        iyz="8.7615523398854E-08"
        izz="0.000116042608880082" />
    </inertial>
    <visual>
      <origin
        xyz="0 0 0"
        rpy="0 0 0" />
      <geometry>
        <mesh
          filename="package://cyber_shopper/meshes/ur5_wrist3_link.STL" />
      </geometry>
      <material
        name="">
        <color
          rgba="0.752941176470588 0.752941176470588 0.752941176470588 1" />
      </material>
    </visual>
    <collision>
      <origin
        xyz="0 0 0"
        rpy="0 0 0" />
      <geometry>
        <mesh
          filename="package://cyber_shopper/meshes/ur5_wrist3_link.STL" />
      </geometry>
    </collision>
  </link>
  <joint
    name="ur5_wrist3_joint"
    type="revolute">
    <origin
      xyz="-0.00023874 -0.08167 0.053725"
      rpy="-1.5708 0 -3.1416" />
    <parent
      link="ur5_wrist2_link" />
    <child
      link="ur5_wrist3_link" />
    <axis
      xyz="0 0 1" />
    <limit
      lower="-6.28"
      upper="6.28"
      effort="0"
      velocity="0" />
  </joint>
  <link
    name="vacuum_gripper_link">
    <inertial>
      <origin
        xyz="1.11022302462516E-16 -2.77555756156289E-17 -0.00500000000000003"
        rpy="0 0 0" />
      <mass
        value="0.0199651354728285" />
      <inertia
        ixx="6.13004074859526E-06"
        ixy="-3.45041739476472E-08"
        ixz="-1.09105449306313E-21"
        iyy="6.29376222934659E-06"
        iyz="2.55818039859143E-20"
        izz="1.20910507200614E-05" />
    </inertial>
    <visual>
      <origin
        xyz="0 0 0"
        rpy="0 0 0" />
      <geometry>
        <mesh
          filename="package://cyber_shopper/meshes/vacuum_gripper_link.STL" />
      </geometry>
      <material
        name="">
        <color
          rgba="0 0 1 1" />
      </material>
    </visual>
    <collision>
      <origin
        xyz="0 0 0"
        rpy="0 0 0" />
      <geometry>
        <mesh
          filename="package://cyber_shopper/meshes/vacuum_gripper_link.STL" />
      </geometry>
    </collision>
  </link>
  <joint
    name="vacuum_gripper_joint"
    type="fixed">
    <origin
      xyz="-0.00014873 -9.0376E-05 0.01"
      rpy="0 0 0" />
    <parent
      link="ur5_wrist3_link" />
    <child
      link="vacuum_gripper_link" />
    <axis
      xyz="0 0 0" />
  </joint>
  <ros2_control name="GazeboSystem" type="system">
 <hardware>
     <plugin>gazebo_ros2_control/GazeboSystem</plugin>
 </hardware>
 # Velocity Controllers
     <joint name="ur5_shoulder_pan_joint">
     <command_interface name="velocity">
         <param name="min">-100000.0</param>
         <param name="max">100000.0</param>
     </command_interface>
     <state_interface name="position"/>
     <state_interface name="velocity"/>
 </joint>

  <joint name="ur5_shoulder_lift_joint">
     <command_interface name="velocity">
         <param name="min">-100000.0</param>
         <param name="max">100000.0</param>
     </command_interface>
     <state_interface name="position"/>
     <state_interface name="velocity"/>
 </joint>
  <joint name="ur5_elbow_joint">
     <command_interface name="velocity">
         <param name="min">-100000.0</param>
         <param name="max">100000.0</param>
     </command_interface>
     <state_interface name="position"/>
     <state_interface name="velocity"/>
 </joint>
<joint name="ur5_wrist1_joint">
    <command_interface name="velocity">
         <param name="min">-100000.0</param>
         <param name="max">100000.0</param>
     </command_interface>
     <state_interface name="position"/>
     <state_interface name="velocity"/>
 </joint>
 <joint name="ur5_wrist2_joint">
    <command_interface name="velocity">
         <param name="min">-100000.0</param>
         <param name="max">100000.0</param>
     </command_interface>
     <state_interface name="position"/>
     <state_interface name="velocity"/>
 </joint>
  <joint name="ur5_wrist3_joint">
     <command_interface name="velocity">
         <param name="min">-100000.0</param>
         <param name="max">100000.0</param>
     </command_interface>
     <state_interface name="position"/>
     <state_interface name="velocity"/>
 </joint>
 <joint name="rr-wheel">
     <command_interface name="velocity">
         <param name="min">-1000.0</param>
         <param name="max">1000.0</param>
     </command_interface>
     <state_interface name="position"/>
     <state_interface name="velocity"/>
 </joint>
 <joint name="rl-wheel">
     <command_interface name="velocity">
         <param name="min">-1000.0</param>
         <param name="max">1000.0</param>
     </command_interface>
     <state_interface name="position"/>
     <state_interface name="velocity"/>
 </joint>
  <joint name="fr-wheel">
     <command_interface name="velocity">
         <param name="min">-1000.0</param>
         <param name="max">1000.0</param>
     </command_interface>
     <state_interface name="position"/>
     <state_interface name="velocity"/>
 </joint>
  <joint name="fl-wheel">
     <command_interface name="velocity">
         <param name="min">-1000.0</param>
         <param name="max">1000.0</param>
     </command_interface>
     <state_interface name="position"/>
     <state_interface name="velocity"/>
 </joint>
 
# Position Controllers
<joint name="ur5_shoulder_pan_joint">
     <command_interface name="position">
         <param name="min">-6.28</param>
         <param name="max">6.28</param>
     </command_interface>
     <state_interface name="position"/>
     <state_interface name="velocity"/>
 </joint>
 <joint name="ur5_shoulder_lift_joint">
     <command_interface name="position">
         <param name="min">-6.28</param>
         <param name="max">6.28</param>
     </command_interface>
     <state_interface name="position"/>
     <state_interface name="velocity"/>
 </joint>

<joint name="ur5_elbow_joint">
     <command_interface name="position">
         <param name="min">-6.28</param>
         <param name="max">6.28</param>
     </command_interface>
     <state_interface name="position"/>
     <state_interface name="velocity"/>
 </joint>
<joint name="ur5_wrist1_joint">
     <command_interface name="position">
         <param name="min">-6.28</param>
         <param name="max">6.28</param>
     </command_interface>
     <state_interface name="position"/>
     <state_interface name="velocity"/>
 </joint>

<joint name="ur5_wrist2_joint">
     <command_interface name="position">
         <param name="min">-6.28</param>
         <param name="max">6.28</param>
     </command_interface>
     <state_interface name="position"/>
     <state_interface name="velocity"/>
 </joint>
 <joint name="ur5_wrist3_joint">
     <command_interface name="position">
         <param name="min">-6.28</param>
         <param name="max">6.28</param>
     </command_interface>
     <state_interface name="position"/>
     <state_interface name="velocity"/>
 </joint>
#cybertruck positioncontrol
 <joint name="fl-hinge">
     <command_interface name="position">
         <param name="min">-3.14</param>
         <param name="max">3.14</param>
     </command_interface>
     <state_interface name="position"/>
     <state_interface name="velocity"/>
 </joint>
 <joint name="fr-hinge">
     <command_interface name="position">
         <param name="min">-3.14</param>
         <param name="max">3.14</param>
     </command_interface>
     <state_interface name="position"/>
     <state_interface name="velocity"/>
 </joint>
 </ros2_control>
<gazebo>
    <plugin filename="libgazebo_ros2_control.so" name="gazebo_ros2_control">
        <parameters>$(find cyber_shopper)/config/control.yaml</parameters>
    </plugin>
</gazebo> 
<gazebo reference="Lidar">
  <sensor name="lidar" type="ray">
    <pose>0.0 0.0 0.0 0 0 0</pose>
    <always_on>true</always_on>
    <visualize>true</visualize>
    <update_rate>5</update_rate>
    <ray>
      <scan>
        <horizontal>
          <samples>360</samples>
          <resolution>1.00000</resolution>
          <min_angle>0.000000</min_angle>
          <max_angle>6.280000</max_angle>
        </horizontal>
      </scan>
      <range>
        <min>0.120000</min>
        <max>3.5</max>
        <resolution>0.015000</resolution>
      </range>
      <noise>
        <type>gaussian</type>
        <mean>0.0</mean>
        <stddev>0.01</stddev>
      </noise>
    </ray>
    <plugin name="scan" filename="libgazebo_ros_ray_sensor.so">
      <ros>
        <remapping>~/out:=scan</remapping>
      </ros>
      <output_type>sensor_msgs/LaserScan</output_type>
      <frame_name>Lidar</frame_name>
    </plugin>
  </sensor>
  </gazebo>
  #IMU
  <gazebo reference="base_link">
  <gravity>true</gravity>
  <sensor name="imu_sensor" type="imu">
    <always_on>true</always_on>
    <update_rate>100</update_rate>
    <visualize>true</visualize>
    <topic>__default_topic__</topic>
    <plugin filename="libgazebo_ros_imu_sensor.so" name="imu_plugin">
      <topicName>imu</topicName>
      <bodyName>base_link</bodyName>
      <updateRateHZ>10.0</updateRateHZ>
      <gaussianNoise>0.0</gaussianNoise>
      <xyzOffset>0 0 0</xyzOffset>
      <rpyOffset>0 0 0</rpyOffset>
      <frameName>base_link</frameName>
      <initialOrientationAsReference>false</initialOrientationAsReference>
    </plugin>
    <pose>0 0 0 0 0 0</pose>
  </sensor>
</gazebo>
#Gripper_Service
<gazebo>
  <plugin name='vacuum_gripper' filename='libgazebo_ros_vacuum_gripper.so'>

    <!-- This part can be commented out if not required -->
    <ros>

      <!-- Add a namespace -->

      <namespace>/demo</namespace>

      <!-- Remapping service and topic names -->
      <remapping>switch:=custom_switch</remapping>
      <remapping>grasping:=custom_grasping</remapping>
    </ros>

    <!-- Link associated with gripper -->
    <link_name>ur5_wrist3_link</link_name>

    <!-- Max distance to attract entities -->
    <max_distance>1.0</max_distance>

    <!-- List of entities to be not attracted by the gripper -->
    <fixed>ground_plane</fixed>
    <fixed>wall</fixed>

  </plugin>
</gazebo>
#Odom plugin
<gazebo>
  <plugin filename="libodometry_plugin.so" name="odometry_plugin">
    <!-- Name of the link for which the odometry is required -->
    <frame>ur5_wrist3_link</frame>
    <!-- Any arbitray name for the world frame -->
    <world_frame>fixed_world</world_frame>
  </plugin>
</gazebo>

</robot>



