<?xml version="1.0" ?>
<!-- This URDF was automatically created by SolidWorks to URDF Exporter! Originally created by Stephen Brawner (brawner@gmail.com) 
     Commit Version: 1.6.0-4-g7f85cfe  Build Version: 1.6.7995.38578
     For more information, please see http://wiki.ros.org/sw_urdf_exporter -->
<robot
  name="car_robot" xmlns:xacro="http://ros.org/wiki/xacro">
  <xacro:macro name="body_color">
    <visual>
    <material>
        <ambient>0.8 0.558823529411765 0.1 1</ambient>
        <diffuse>0.8 0.558823529411765 0.1 1</diffuse>
        <specular>0.1 0.1 0.1 1</specular>
        <emissive>0 0 0 0</emissive>
    </material>
    </visual>
</xacro:macro>
<gazebo reference="base_link">
    <xacro:body_color />
</gazebo>
  <link
    name="base_link">
    <inertial>
      <origin
        xyz="-0.00677096096599197 -7.40324229928916E-09 0.0650709573527417"
        rpy="0 0 0" />
      <mass
        value="40.1297473551325" />
      <inertia
        ixx="1.26922453974044"
        ixy="1.04912166639753E-07"
        ixz="-0.0347492884684778"
        iyy="3.34453299992272"
        iyz="1.6440457327724E-08"
        izz="4.11157029873108" />
    </inertial>
    <visual>
      <origin
        xyz="0 0 0"
        rpy="0 0 0" />
      <geometry>
        <mesh
          filename="package://car_robot/meshes/base_link.STL" />
      </geometry>
      <material
        name="">
        <color
          rgba="0.752941176470588 0.752941176470588 0.752941176470588 1" />
      </material>
    </visual>
    <collision>
      <origin
        xyz="0 0 0"
        rpy="0 0 0" />
      <geometry>
        <mesh
          filename="package://car_robot/meshes/base_link.STL" />
      </geometry>
    </collision>
  </link>
  <link
    name="front-left-hinge">
    <inertial>
      <origin
        xyz="0 2.77555756156289E-17 -0.118799628145585"
        rpy="0 0 0" />
      <mass
        value="0.633612488698204" />
      <inertia
        ixx="0.0042046227153009"
        ixy="-0.000142990919869844"
        ixz="-1.30495243379754E-18"
        iyy="0.00247147692758528"
        iyz="-6.30427138270604E-19"
        izz="0.00202629416547586" />
    </inertial>
    <visual>
      <origin
        xyz="0 0 0"
        rpy="0 0 0" />
      <geometry>
        <mesh
          filename="package://car_robot/meshes/front-left-hinge.STL" />
      </geometry>
      <material
        name="">
        <color
          rgba="1 1 0 1" />
      </material>
    </visual>
    <collision>
      <origin
        xyz="0 0 0"
        rpy="0 0 0" />
      <geometry>
        <mesh
          filename="package://car_robot/meshes/front-left-hinge.STL" />
      </geometry>
    </collision>
  </link>
  <joint
    name="fl-hinge"
    type="continuous">
    <origin
      xyz="0.254 0.1397 0.0608"
      rpy="0 0 -3.1416" />
    <parent
      link="base_link" />
    <child
      link="front-left-hinge" />
    <axis
      xyz="0 0 -1" />
    <limit
      lower="-0.69"
      upper="0.69"
      effort="0"
      velocity="0" />
  </joint>
  <link
    name="front-left-wheeel">
    <inertial>
      <origin
        xyz="0.00622369727134658 -2.77555756156289E-16 -0.0759454119237928"
        rpy="0 0 0" />
      <mass
        value="2.43249992415545" />
      <inertia
        ixx="0.00758718354662836"
        ixy="-1.26731196831282E-18"
        ixz="-0.000423171308923178"
        iyy="0.00755250482076537"
        iyz="-1.68232117058127E-19"
        izz="0.0127163034390655" />
    </inertial>
    <visual>
      <origin
        xyz="0 0 0"
        rpy="0 0 0" />
      <geometry>
        <mesh
          filename="package://car_robot/meshes/front-left-wheeel.STL" />
      </geometry>
      <material
        name="">
        <color
          rgba="0 0 0 1" />
      </material>
    </visual>
    <collision>
      <origin
        xyz="0 0 0"
        rpy="0 0 0" />
      <geometry>
        <mesh
          filename="package://car_robot/meshes/front-left-wheeel.STL" />
      </geometry>
    </collision>
  </link>
  <joint
    name="fl-wheel"
    type="continuous">
    <origin
      xyz="-0.00622369727134681 -0.0759454119237924 -0.2005"
      rpy="1.5707963267949 0 0" />
    <parent
      link="front-left-hinge" />
    <child
      link="front-left-wheeel" />
    <axis
      xyz="-0.0816758172092811 0 0.996658949131144" />
    <limit
      lower="0"
      upper="0"
      effort="0"
      velocity="0" />
  </joint>
  <link
    name="front-left-axle">
    <inertial>
      <origin
        xyz="0.00622369727134719 -5.55111512312578E-17 -0.0759454119237932"
        rpy="0 0 0" />
      <mass
        value="0.0772222198144586" />
      <inertia
        ixx="0.000151599574572288"
        ixy="4.39662991317288E-21"
        ixz="1.19131785081697E-05"
        iyy="0.000152575854964957"
        iyz="-5.36504034940161E-20"
        izz="7.203866309606E-06" />
    </inertial>
    <visual>
      <origin
        xyz="0 0 0"
        rpy="0 0 0" />
      <geometry>
        <mesh
          filename="package://car_robot/meshes/front-left-axle.STL" />
      </geometry>
      <material
        name="">
        <color
          rgba="0.792156862745098 0.819607843137255 0.933333333333333 1" />
      </material>
    </visual>
    <collision>
      <origin
        xyz="0 0 0"
        rpy="0 0 0" />
      <geometry>
        <mesh
          filename="package://car_robot/meshes/front-left-axle.STL" />
      </geometry>
    </collision>
  </link>
  <joint
    name="fl-axle"
    type="fixed">
    <origin
      xyz="-0.00622369727134681 -0.0759454119237924 -0.2005"
      rpy="1.5707963267949 0 0" />
    <parent
      link="front-left-hinge" />
    <child
      link="front-left-axle" />
    <axis
      xyz="-0.0816758172092811 0 0.996658949131144" />
    <limit
      lower="0"
      upper="0"
      effort="0"
      velocity="0" />
  </joint>
  <link
    name="front-right-hinge">
    <inertial>
      <origin
        xyz="0 -1.38777878078145E-16 -0.118799628145585"
        rpy="0 0 0" />
      <mass
        value="0.633612488698205" />
      <inertia
        ixx="0.00421634076613872"
        ixy="1.97169687775791E-19"
        ixz="3.34139793073233E-19"
        iyy="0.00245975887674748"
        iyz="-4.58614596323022E-19"
        izz="0.00202629416547586" />
    </inertial>
    <visual>
      <origin
        xyz="0 0 0"
        rpy="0 0 0" />
      <geometry>
        <mesh
          filename="package://car_robot/meshes/front-right-hinge.STL" />
      </geometry>
      <material
        name="">
        <color
          rgba="1 1 0 1" />
      </material>
    </visual>
    <collision>
      <origin
        xyz="0 0 0"
        rpy="0 0 0" />
      <geometry>
        <mesh
          filename="package://car_robot/meshes/front-right-hinge.STL" />
      </geometry>
    </collision>
  </link>
  <joint
    name="fr-hinge"
    type="continuous">
    <origin
      xyz="0.254 -0.1397 0.0608"
      rpy="0 0 -3.1416" />
    <parent
      link="base_link" />
    <child
      link="front-right-hinge" />
    <axis
      xyz="0 0 -1" />
    <limit
      lower="-0.69"
      upper="0.69"
      effort="0"
      velocity="0" />
  </joint>
  <link
    name="front-right-wheel">
    <inertial>
      <origin
        xyz="0 2.77555756156289E-17 -0.0762"
        rpy="0 0 0" />
      <mass
        value="2.43249992415545" />
      <inertia
        ixx="0.00755250482076537"
        ixy="-1.41203303983048E-19"
        ixz="1.30750629116003E-18"
        iyy="0.00755250482076537"
        iyz="-3.76415922197689E-18"
        izz="0.0127509821649285" />
    </inertial>
    <visual>
      <origin
        xyz="0 0 0"
        rpy="0 0 0" />
      <geometry>
        <mesh
          filename="package://car_robot/meshes/front-right-wheel.STL" />
      </geometry>
      <material
        name="">
        <color
          rgba="0 0 0 1" />
      </material>
    </visual>
    <collision>
      <origin
        xyz="0 0 0"
        rpy="0 0 0" />
      <geometry>
        <mesh
          filename="package://car_robot/meshes/front-right-wheel.STL" />
      </geometry>
    </collision>
  </link>
  <joint
    name="fr-wheel"
    type="continuous">
    <origin
      xyz="0 0.0761999999999998 -0.2005"
      rpy="1.5707963267949 0 3.14159265358979" />
    <parent
      link="front-right-hinge" />
    <child
      link="front-right-wheel" />
    <axis
      xyz="0 0 -1" />
    <limit
      lower="0"
      upper="0"
      effort="0"
      velocity="0" />
  </joint>
  <link
    name="front-right-axle">
    <inertial>
      <origin
        xyz="0 5.55111512312578E-17 -0.0762"
        rpy="0 0 0" />
      <mass
        value="0.0772222198144586" />
      <inertia
        ixx="0.000152575854964957"
        ixy="7.03302044017091E-22"
        ixz="-2.70384489878801E-22"
        iyy="0.000152575854964957"
        iyz="9.66801247676817E-20"
        izz="6.22758591693701E-06" />
    </inertial>
    <visual>
      <origin
        xyz="0 0 0"
        rpy="0 0 0" />
      <geometry>
        <mesh
          filename="package://car_robot/meshes/front-right-axle.STL" />
      </geometry>
      <material
        name="">
        <color
          rgba="0.792156862745098 0.819607843137255 0.933333333333333 1" />
      </material>
    </visual>
    <collision>
      <origin
        xyz="0 0 0"
        rpy="0 0 0" />
      <geometry>
        <mesh
          filename="package://car_robot/meshes/front-right-axle.STL" />
      </geometry>
    </collision>
  </link>
  <joint
    name="fr-axle"
    type="fixed">
    <origin
      xyz="0 0.0761999999999998 -0.2005"
      rpy="1.5707963267949 0 3.14159265358979" />
    <parent
      link="front-right-hinge" />
    <child
      link="front-right-axle" />
    <axis
      xyz="0.170506745557827 0 0.985356508944493" />
    <limit
      lower="0"
      upper="0"
      effort="0"
      velocity="0" />
  </joint>
  <link
    name="rear-left-wheel">
    <inertial>
      <origin
        xyz="-1.66533453693773E-16 -5.55111512312578E-17 -0.0762"
        rpy="0 0 0" />
      <mass
        value="2.43249992415545" />
      <inertia
        ixx="0.00755250482076536"
        ixy="-8.23812994843201E-19"
        ixz="-1.50602458021814E-19"
        iyy="0.00755250482076536"
        iyz="2.88296133927474E-19"
        izz="0.0127509821649285" />
    </inertial>
    <visual>
      <origin
        xyz="0 0 0"
        rpy="0 0 0" />
      <geometry>
        <mesh
          filename="package://car_robot/meshes/rear-left-wheel.STL" />
      </geometry>
      <material
        name="">
        <color
          rgba="0 0 0 1" />
      </material>
    </visual>
    <collision>
      <origin
        xyz="0 0 0"
        rpy="0 0 0" />
      <geometry>
        <mesh
          filename="package://car_robot/meshes/rear-left-wheel.STL" />
      </geometry>
    </collision>
  </link>
  <joint
    name="rl-wheel"
    type="continuous">
    <origin
      xyz="-0.254 0.2159 -0.1397"
      rpy="1.5708 0 -3.1416" />
    <parent
      link="base_link" />
    <child
      link="rear-left-wheel" />
    <axis
      xyz="0 0 -1" />
    <limit
      lower="0"
      upper="0"
      effort="0"
      velocity="0" />
  </joint>
  <link
    name="rear-left-axle">
    <inertial>
      <origin
        xyz="0 0 -0.0762"
        rpy="0 0 0" />
      <mass
        value="0.0772222198144586" />
      <inertia
        ixx="0.000152575854964957"
        ixy="6.89140711930171E-22"
        ixz="-5.62078824877413E-21"
        iyy="0.000152575854964957"
        iyz="-2.78728394910108E-20"
        izz="6.22758591693701E-06" />
    </inertial>
    <visual>
      <origin
        xyz="0 0 0"
        rpy="0 0 0" />
      <geometry>
        <mesh
          filename="package://car_robot/meshes/rear-left-axle.STL" />
      </geometry>
      <material
        name="">
        <color
          rgba="0.792156862745098 0.819607843137255 0.933333333333333 1" />
      </material>
    </visual>
    <collision>
      <origin
        xyz="0 0 0"
        rpy="0 0 0" />
      <geometry>
        <mesh
          filename="package://car_robot/meshes/rear-left-axle.STL" />
      </geometry>
    </collision>
  </link>
  <joint
    name="rl-axle"
    type="fixed">
    <origin
      xyz="-0.254 0.2159 -0.1397"
      rpy="1.5708 0 -3.1416" />
    <parent
      link="base_link" />
    <child
      link="rear-left-axle" />
    <axis
      xyz="0 0 0" />
    <limit
      lower="0"
      upper="0"
      effort="0"
      velocity="0" />
  </joint>
  <link
    name="rear-right-wheel">
    <inertial>
      <origin
        xyz="5.55111512312578E-17 2.77555756156289E-17 -0.0762"
        rpy="0 0 0" />
      <mass
        value="2.43249992415545" />
      <inertia
        ixx="0.00755250482076537"
        ixy="1.16151947225978E-18"
        ixz="3.90126123152596E-19"
        iyy="0.00755250482076537"
        iyz="7.17453761935092E-19"
        izz="0.0127509821649285" />
    </inertial>
    <visual>
      <origin
        xyz="0 0 0"
        rpy="0 0 0" />
      <geometry>
        <mesh
          filename="package://car_robot/meshes/rear-right-wheel.STL" />
      </geometry>
      <material
        name="">
        <color
          rgba="0 0 0 1" />
      </material>
    </visual>
    <collision>
      <origin
        xyz="0 0 0"
        rpy="0 0 0" />
      <geometry>
        <mesh
          filename="package://car_robot/meshes/rear-right-wheel.STL" />
      </geometry>
    </collision>
  </link>
  <joint
    name="rr-wheel"
    type="continuous">
    <origin
      xyz="-0.254 -0.2159 -0.1397"
      rpy="1.5708 0 0" />
    <parent
      link="base_link" />
    <child
      link="rear-right-wheel" />
    <axis
      xyz="0 0 -1" />
    <limit
      lower="0"
      upper="0"
      effort="0"
      velocity="0" />
  </joint>
  <link
    name="rear-right-axle">
    <inertial>
      <origin
        xyz="0 2.77555756156289E-17 -0.0762"
        rpy="0 0 0" />
      <mass
        value="0.0772222198144586" />
      <inertia
        ixx="0.000152575854964957"
        ixy="-5.62062593584521E-37"
        ixz="-5.0774755597234E-21"
        iyy="0.000152575854964957"
        iyz="-1.62003512769673E-20"
        izz="6.22758591693702E-06" />
    </inertial>
    <visual>
      <origin
        xyz="0 0 0"
        rpy="0 0 0" />
      <geometry>
        <mesh
          filename="package://car_robot/meshes/rear-right-axle.STL" />
      </geometry>
      <material
        name="">
        <color
          rgba="0.792156862745098 0.819607843137255 0.933333333333333 1" />
      </material>
    </visual>
    <collision>
      <origin
        xyz="0 0 0"
        rpy="0 0 0" />
      <geometry>
        <mesh
          filename="package://car_robot/meshes/rear-right-axle.STL" />
      </geometry>
    </collision>
  </link>
  <joint
    name="rr-axle"
    type="fixed">
    <origin
      xyz="-0.254 -0.2159 -0.1397"
      rpy="1.5708 0 0" />
    <parent
      link="base_link" />
    <child
      link="rear-right-axle" />
    <axis
      xyz="0 0 0" />
    <limit
      lower="0"
      upper="0"
      effort="0"
      velocity="0" />
  </joint>
  <link
    name="Lidar">
    <inertial>
      <origin
        xyz="0 -1.02751096627556E-17 -0.08905"
        rpy="0 0 0" />
      <mass
        value="0.0902446020272643" />
      <inertia
        ixx="0.000242182519707747"
        ixy="9.5944127796284E-22"
        ixz="-6.99487317772809E-21"
        iyy="0.000242182519707747"
        iyz="-2.72604477775199E-20"
        izz="7.27777593048873E-06" />
    </inertial>
    <visual>
      <origin
        xyz="0 0 0"
        rpy="0 0 0" />
      <geometry>
        <mesh
          filename="package://car_robot/meshes/Lidar.STL" />
      </geometry>
      <material
        name="">
        <color
          rgba="0 0 0 1" />
      </material>
    </visual>
    <collision>
      <origin
        xyz="0 0 0"
        rpy="0 0 0" />
      <geometry>
        <mesh
          filename="package://car_robot/meshes/Lidar.STL" />
      </geometry>
    </collision>
  </link>
  <joint
    name="l-sensor"
    type="fixed">
    <origin
      xyz="0.45 0 0.1781"
      rpy="0 0 0" />
    <parent
      link="base_link" />
    <child
      link="Lidar" />
    <axis
      xyz="0 0 0" />
  </joint>
     <ros2_control name="GazeboSystem" type="system">
 <hardware>
     <plugin>gazebo_ros2_control/GazeboSystem</plugin>
 </hardware>
 # Velocity Controllers

 <joint name="rr-wheel">
     <command_interface name="velocity">
         <param name="min">-1000.0</param>
         <param name="max">1000.0</param>
     </command_interface>
     <state_interface name="position"/>
     <state_interface name="velocity"/>
 </joint>
 <joint name="rl-wheel">
     <command_interface name="velocity">
         <param name="min">-1000.0</param>
         <param name="max">1000.0</param>
     </command_interface>
     <state_interface name="position"/>
     <state_interface name="velocity"/>
 </joint>
  <joint name="fr-wheel">
     <command_interface name="velocity">
         <param name="min">-1000.0</param>
         <param name="max">1000.0</param>
     </command_interface>
     <state_interface name="position"/>
     <state_interface name="velocity"/>
 </joint>
  <joint name="fl-wheel">
     <command_interface name="velocity">
         <param name="min">-1000.0</param>
         <param name="max">1000.0</param>
     </command_interface>
     <state_interface name="position"/>
     <state_interface name="velocity"/>
 </joint>
# Position Controller
 <joint name="fl-axle">
     <command_interface name="position">
         <param name="min">-3.14</param>
         <param name="max">3.14</param>
     </command_interface>
     <state_interface name="position"/>
     <state_interface name="velocity"/>
 </joint>
 <joint name="fr-axle">
     <command_interface name="position">
         <param name="min">-3.14</param>
         <param name="max">3.14</param>
     </command_interface>
     <state_interface name="position"/>
     <state_interface name="velocity"/>
 </joint>
 </ros2_control>
<gazebo>
    <plugin filename="libgazebo_ros2_control.so" name="gazebo_ros2_control">
        <parameters>$(find car_robot)/config/control.yaml</parameters>
    </plugin>
</gazebo> 
</robot>