<?xml version="1.0" ?>
<!-- This URDF was automatically created by SolidWorks to URDF Exporter! Originally created by Stephen Brawner (brawner@gmail.com) 
     Commit Version: 1.6.0-4-g7f85cfe  Build Version: 1.6.7995.38578
     For more information, please see http://wiki.ros.org/sw_urdf_exporter -->
<robot
  name="car_robot" xmlns:xacro="http://ros.org/wiki/xacro">
  <link
    name="base_link">
    <inertial>
      <origin
        xyz="-0.00677096096599193 -7.40324228051496E-09 0.0650709573527417"
        rpy="0 0 0" />
      <mass
        value="40.1297473551325" />
      <inertia
        ixx="1.26922453974044"
        ixy="1.04912166627371E-07"
        ixz="-0.0347492884684778"
        iyy="3.34453299992272"
        iyz="1.64404574516637E-08"
        izz="4.11157029873108" />
    </inertial>
    <visual>
      <origin
        xyz="0 0 0"
        rpy="0 0 0" />
      <geometry>
        <mesh
          filename="package://car_robot/meshes/base_link.STL" />
      </geometry>
      <material
        name="">
        <color
          rgba="0.752941176470588 0.752941176470588 0.752941176470588 1" />
      </material>
    </visual>
    <collision>
      <origin
        xyz="0 0 0"
        rpy="0 0 0" />
      <geometry>
        <mesh
          filename="package://car_robot/meshes/base_link.STL" />
      </geometry>
    </collision>
  </link>
  <link
    name="front-left-hinge">
    <inertial>
      <origin
        xyz="0 0 -0.118799628145585"
        rpy="0 0 0" />
      <mass
        value="0.633612488698205" />
      <inertia
        ixx="0.00421598497152854"
        ixy="2.499711540899E-05"
        ixz="-1.35033902121542E-18"
        iyy="0.00246011467135765"
        iyz="2.20234865744933E-19"
        izz="0.00202629416547586" />
    </inertial>
    <visual>
      <origin
        xyz="0 0 0"
        rpy="0 0 0" />
      <geometry>
        <mesh
          filename="package://car_robot/meshes/front-left-hinge.STL" />
      </geometry>
      <material
        name="">
        <color
          rgba="1 1 0 1" />
      </material>
    </visual>
    <collision>
      <origin
        xyz="0 0 0"
        rpy="0 0 0" />
      <geometry>
        <mesh
          filename="package://car_robot/meshes/front-left-hinge.STL" />
      </geometry>
    </collision>
  </link>
  <joint
    name="fl-hinge"
    type="revolute">
    <origin
      xyz="0.254 0.1397 0.0608"
      rpy="0 0 -3.1416" />
    <parent
      link="base_link" />
    <child
      link="front-left-hinge" />
    <axis
      xyz="0 0 -1" />
    <limit
      lower="-3.14"
      upper="3.14"
      effort="0"
      velocity="0" />
  </joint>
  <link
    name="front-left-wheeel">
    <inertial>
      <origin
        xyz="0.00108447726862249 1.11022302462516E-16 0.0761922824769925"
        rpy="0 0 0" />
      <mass
        value="2.43249992415545" />
      <inertia
        ixx="0.00755355776923952"
        ixy="1.88640504073853E-18"
        ixz="7.39771592248954E-05"
        iyy="0.00755250482076537"
        iyz="1.95246869510358E-18"
        izz="0.0127499292164544" />
    </inertial>
    <visual>
      <origin
        xyz="0 0 0"
        rpy="0 0 0" />
      <geometry>
        <mesh
          filename="package://car_robot/meshes/front-left-wheeel.STL" />
      </geometry>
      <material
        name="">
        <color
          rgba="0 0 0 1" />
      </material>
    </visual>
    <collision>
      <origin
        xyz="0 0 0"
        rpy="0 0 0" />
      <geometry>
        <mesh
          filename="package://car_robot/meshes/front-left-wheeel.STL" />
      </geometry>
    </collision>
  </link>
  <joint
    name="fl-wheel"
    type="continuous">
    <origin
      xyz="-0.00108447726862265 0.0761922824769925 -0.2005"
      rpy="1.5707963267949 0 0" />
    <parent
      link="front-left-hinge" />
    <child
      link="front-left-wheeel" />
    <axis
      xyz="-0.0142319851525261 0 -0.999898720170507" />
    <limit
      lower="0"
      upper="0"
      effort="0"
      velocity="0" />
  </joint>
  <link
    name="front-right-hinge">
    <inertial>
      <origin
        xyz="-5.55111512312578E-17 -5.55111512312578E-17 -0.118799628145585"
        rpy="0 0 0" />
      <mass
        value="0.633612488698205" />
      <inertia
        ixx="0.00421634076613872"
        ixy="3.80852095203232E-19"
        ixz="1.69567032741007E-18"
        iyy="0.00245975887674748"
        iyz="9.55878885787063E-19"
        izz="0.00202629416547586" />
    </inertial>
    <visual>
      <origin
        xyz="0 0 0"
        rpy="0 0 0" />
      <geometry>
        <mesh
          filename="package://car_robot/meshes/front-right-hinge.STL" />
      </geometry>
      <material
        name="">
        <color
          rgba="1 1 0 1" />
      </material>
    </visual>
    <collision>
      <origin
        xyz="0 0 0"
        rpy="0 0 0" />
      <geometry>
        <mesh
          filename="package://car_robot/meshes/front-right-hinge.STL" />
      </geometry>
    </collision>
  </link>
  <joint
    name="fr-hinge"
    type="revolute">
    <origin
      xyz="0.254 -0.1397 0.0608"
      rpy="0 0 -3.1416" />
    <parent
      link="base_link" />
    <child
      link="front-right-hinge" />
    <axis
      xyz="0 0 -1" />
    <limit
      lower="-3.14"
      upper="3.14"
      effort="0"
      velocity="0" />
  </joint>
  <link
    name="front-right-wheel">
    <inertial>
      <origin
        xyz="-5.55111512312578E-17 0 -0.0762"
        rpy="0 0 0" />
      <mass
        value="2.43249992415545" />
      <inertia
        ixx="0.00755250482076537"
        ixy="6.00508507818468E-19"
        ixz="8.35496005193151E-19"
        iyy="0.00755250482076537"
        iyz="-3.98615026528919E-18"
        izz="0.0127509821649285" />
    </inertial>
    <visual>
      <origin
        xyz="0 0 0"
        rpy="0 0 0" />
      <geometry>
        <mesh
          filename="package://car_robot/meshes/front-right-wheel.STL" />
      </geometry>
      <material
        name="">
        <color
          rgba="0 0 0 1" />
      </material>
    </visual>
    <collision>
      <origin
        xyz="0 0 0"
        rpy="0 0 0" />
      <geometry>
        <mesh
          filename="package://car_robot/meshes/front-right-wheel.STL" />
      </geometry>
    </collision>
  </link>
  <joint
    name="fr-wheel"
    type="continuous">
    <origin
      xyz="0 0.0761999999999999 -0.2005"
      rpy="1.5707963267949 0 3.14159265358979" />
    <parent
      link="front-right-hinge" />
    <child
      link="front-right-wheel" />
    <axis
      xyz="0 0 -1" />
    <limit
      lower="0"
      upper="0"
      effort="0"
      velocity="0" />
  </joint>
  <link
    name="Lidar">
    <inertial>
      <origin
        xyz="0 -1.02751096627556E-17 -0.08905"
        rpy="0 0 0" />
      <mass
        value="0.0902446020272643" />
      <inertia
        ixx="0.000242182519707747"
        ixy="9.5944127796284E-22"
        ixz="-6.99487317772809E-21"
        iyy="0.000242182519707747"
        iyz="-2.72604477775199E-20"
        izz="7.27777593048873E-06" />
    </inertial>
    <visual>
      <origin
        xyz="0 0 0"
        rpy="0 0 0" />
      <geometry>
        <mesh
          filename="package://car_robot/meshes/Lidar.STL" />
      </geometry>
      <material
        name="">
        <color
          rgba="0 0 0 1" />
      </material>
    </visual>
    <collision>
      <origin
        xyz="0 0 0"
        rpy="0 0 0" />
      <geometry>
        <mesh
          filename="package://car_robot/meshes/Lidar.STL" />
      </geometry>
    </collision>
  </link>
  <joint
    name="l-sensor"
    type="fixed">
    <origin
      xyz="0.45 0 0.1781"
      rpy="0 0 0" />
    <parent
      link="base_link" />
    <child
      link="Lidar" />
    <axis
      xyz="0 0 0" />
  </joint>
  <link
    name="rear-right-wheel">
    <inertial>
      <origin
        xyz="5.55111512312578E-17 2.77555756156289E-17 -0.0762"
        rpy="0 0 0" />
      <mass
        value="2.43249992415545" />
      <inertia
        ixx="0.00755250482076537"
        ixy="1.16151947225978E-18"
        ixz="3.90126123152596E-19"
        iyy="0.00755250482076537"
        iyz="7.17453761935092E-19"
        izz="0.0127509821649285" />
    </inertial>
    <visual>
      <origin
        xyz="0 0 0"
        rpy="0 0 0" />
      <geometry>
        <mesh
          filename="package://car_robot/meshes/rear-right-wheel.STL" />
      </geometry>
      <material
        name="">
        <color
          rgba="0 0 0 1" />
      </material>
    </visual>
    <collision>
      <origin
        xyz="0 0 0"
        rpy="0 0 0" />
      <geometry>
        <mesh
          filename="package://car_robot/meshes/rear-right-wheel.STL" />
      </geometry>
    </collision>
  </link>
  <joint
    name="rr-wheel"
    type="continuous">
    <origin
      xyz="-0.254 -0.2159 -0.1397"
      rpy="1.5708 0 0" />
    <parent
      link="base_link" />
    <child
      link="rear-right-wheel" />
    <axis
      xyz="0 0 -1" />
    <limit
      lower="0"
      upper="0"
      effort="0"
      velocity="0" />
  </joint>
  <link
    name="rear-left-wheel">
    <inertial>
      <origin
        xyz="-1.66533453693773E-16 -5.55111512312578E-17 -0.0762"
        rpy="0 0 0" />
      <mass
        value="2.43249992415545" />
      <inertia
        ixx="0.00755250482076536"
        ixy="-8.23812994843201E-19"
        ixz="-1.50602458021814E-19"
        iyy="0.00755250482076536"
        iyz="2.88296133927474E-19"
        izz="0.0127509821649285" />
    </inertial>
    <visual>
      <origin
        xyz="0 0 0"
        rpy="0 0 0" />
      <geometry>
        <mesh
          filename="package://car_robot/meshes/rear-left-wheel.STL" />
      </geometry>
      <material
        name="">
        <color
          rgba="0 0 0 1" />
      </material>
    </visual>
    <collision>
      <origin
        xyz="0 0 0"
        rpy="0 0 0" />
      <geometry>
        <mesh
          filename="package://car_robot/meshes/rear-left-wheel.STL" />
      </geometry>
    </collision>
  </link>
  <joint
    name="rl-wheel"
    type="continuous">
    <origin
      xyz="-0.254 0.2159 -0.1397"
      rpy="1.5707963267949 0 -3.14159265358979" />
    <parent
      link="base_link" />
    <child
      link="rear-left-wheel" />
    <axis
      xyz="0 0 -1" />
    <limit
      lower="0"
      upper="0"
      effort="0"
      velocity="0" />
  </joint>
     <ros2_control name="GazeboSystem" type="system">
 <hardware>
     <plugin>gazebo_ros2_control/GazeboSystem</plugin>
 </hardware>
 # Velocity Controllers

 <joint name="rr-wheel">
     <command_interface name="velocity">
         <param name="min">-1000.0</param>
         <param name="max">1000.0</param>
     </command_interface>
     <state_interface name="position"/>
     <state_interface name="velocity"/>
 </joint>
 <joint name="rl-wheel">
     <command_interface name="velocity">
         <param name="min">-1000.0</param>
         <param name="max">1000.0</param>
     </command_interface>
     <state_interface name="position"/>
     <state_interface name="velocity"/>
 </joint>
  <joint name="fr-wheel">
     <command_interface name="velocity">
         <param name="min">-1000.0</param>
         <param name="max">1000.0</param>
     </command_interface>
     <state_interface name="position"/>
     <state_interface name="velocity"/>
 </joint>
  <joint name="fl-wheel">
     <command_interface name="velocity">
         <param name="min">-1000.0</param>
         <param name="max">1000.0</param>
     </command_interface>
     <state_interface name="position"/>
     <state_interface name="velocity"/>
 </joint>
# Position Controller
 <joint name="fl-hinge">
     <command_interface name="position">
         <param name="min">-3.14</param>
         <param name="max">3.14</param>
     </command_interface>
     <state_interface name="position"/>
     <state_interface name="velocity"/>
 </joint>
 <joint name="fr-hinge">
     <command_interface name="position">
         <param name="min">-3.14</param>
         <param name="max">3.14</param>
     </command_interface>
     <state_interface name="position"/>
     <state_interface name="velocity"/>
 </joint>
 </ros2_control>
<gazebo>
    <plugin filename="libgazebo_ros2_control.so" name="gazebo_ros2_control">
        <parameters>$(find car_robot)/config/control.yaml</parameters>
    </plugin>
</gazebo> 
</robot>
