<?xml version="1.0" ?>
<!-- This URDF was automatically created by SolidWorks to URDF Exporter! Originally created by Stephen Brawner (brawner@gmail.com) 
     Commit Version: 1.6.0-4-g7f85cfe  Build Version: 1.6.7995.38578
     For more information, please see http://wiki.ros.org/sw_urdf_exporter -->
<robot
  name="car_robot" xmlns:xacro="http://ros.org/wiki/xacro">
  <xacro:macro name="body_color">
    <visual>
    <material>
        <ambient>0.5 0.5 0.5 1.0</ambient>
        <diffuse>0.5 0.5 0.5 1.0</diffuse>
        <specular>0.7 0.7 0.7 1.0</specular>
        <emissive>0 0 0 1.0</emissive>
    </material>
    </visual>
  </xacro:macro>
<gazebo reference="base_link">
    <xacro:body_color />
</gazebo>
  <xacro:macro name="fr_wheel_color">
    <visual>
    <material>
        <ambient>0 0 0 1.0</ambient>
        <diffuse>0 0 0 1.0</diffuse>
        <specular>0 0 0 1.0</specular>
        <emissive>0 0 0 1.0</emissive>
    </material>
    </visual>
  </xacro:macro>
<gazebo reference="front-right-wheel">
    <xacro:fr_wheel_color/>
</gazebo>
<xacro:macro name="fl_wheel_color">
    <visual>
    <material>
        <ambient>0 0 0 1.0</ambient>
        <diffuse>0 0 0 1.0</diffuse>
        <specular>0 0 0 1.0</specular>
        <emissive>0 0 0 1.0</emissive>
    </material>
    </visual>
  </xacro:macro>
<gazebo reference="front-left-wheel">
    <xacro:fl_wheel_color/>
</gazebo>
<xacro:macro name="rr_wheel_color">
    <visual>
    <material>
        <ambient>0 0 0 1.0</ambient>
        <diffuse>0 0 0 1.0</diffuse>
        <specular>0 0 0 1.0</specular>
        <emissive>0 0 0 1.0</emissive>
    </material>
    </visual>
  </xacro:macro>
<gazebo reference="rear-right-wheel">
    <xacro:rr_wheel_color/>
</gazebo>
<xacro:macro name="rl_wheel_color">
    <visual>
    <material>
        <ambient>0 0 0 1.0</ambient>
        <diffuse>0 0 0 1.0</diffuse>
        <specular>0 0 0 1.0</specular>
        <emissive>0 0 0 1.0</emissive>
    </material>
    </visual>
  </xacro:macro>
<gazebo reference="rear-left-wheel">
    <xacro:rl_wheel_color/>
</gazebo>
<xacro:macro name="Lidar">
<visual>
    <material>
        <ambient>0 0 0 1.0</ambient>
        <diffuse>0 0 0 1.0</diffuse>
        <specular>0 0 0 1.0</specular>
        <emissive>0 0 0 1.0</emissive>
    </material>
    </visual>
  </xacro:macro>
<gazebo reference="Lidar">
    <xacro:Lidar/>
</gazebo>
  <xacro:macro name="righthinge">
    <visual>
    <material>
        <ambient>0.8 0.558823529411765 0.1 1</ambient>
        <diffuse>0.8 0.558823529411765 0.1 1</diffuse>
        <specular>0.1 0.1 0.1 1</specular>
        <emissive>0 0 0 0</emissive>
    </material>
    </visual>
</xacro:macro>
<gazebo reference="front-right-hinge">
    <xacro:righthinge />
</gazebo>
  <xacro:macro name="left-hinge">
    <visual>
    <material>
        <ambient>0.8 0.558823529411765 0.1 1</ambient>
        <diffuse>0.8 0.558823529411765 0.1 1</diffuse>
        <specular>0.1 0.1 0.1 1</specular>
        <emissive>0 0 0 0</emissive>
    </material>
    </visual>
</xacro:macro>
<gazebo reference="front-left-hinge">
    <xacro:left-hinge />
</gazebo>


# Add this before base link
<link name="dummy_link"></link>


  <link
    name="base_link">
    <inertial>
      <origin
        xyz="-0.00590761615173888 8.73355505905299E-10 0.0651857188195396"
        rpy="0 0 0" />
      <mass
        value="40.2057306762447" />
      <inertia
        ixx="1.26964977918221"
        ixy="-1.56502914706543E-08"
        ixz="-0.0368531498128534"
        iyy="3.36078463885119"
        iyz="1.85572003306758E-12"
        izz="4.12740286196387" />
    </inertial>
    <visual>
      <origin
        xyz="0 0 0"
        rpy="0 0 0" />
      <geometry>
        <mesh
          filename="package://car_robot/meshes/base_link.STL" />
      </geometry>
      <material
        name="">
        <color
          rgba="0.752941176470588 0.752941176470588 0.752941176470588 1" />
      </material>
    </visual>
    <collision>
      <origin
        xyz="0 0 0"
        rpy="0 0 0" />
      <geometry>
        <mesh
          filename="package://car_robot/meshes/base_link.STL" />
      </geometry>
    </collision>
  </link>
  # Add this after base link
<joint name="dummy_joint" type="fixed">
    <origin rpy="0 0 0" xyz="0 0 0" />
    <parent link="dummy_link"/>
    <child link="base_link"/>
</joint>
  <link
    name="front-left-hinge">
    <inertial>
      <origin
        xyz="5.55111512312578E-17 2.77555756156289E-17 -0.118799628145585"
        rpy="0 0 0" />
      <mass
        value="0.633612488698204" />
      <inertia
        ixx="0.00421598497152854"
        ixy="2.499711540899E-05"
        ixz="1.39648971177733E-18"
        iyy="0.00246011467135765"
        iyz="-2.46632049893864E-19"
        izz="0.00202629416547586" />
    </inertial>
    <visual>
      <origin
        xyz="0 0 0"
        rpy="0 0 0" />
      <geometry>
        <mesh
          filename="package://car_robot/meshes/front-left-hinge.STL" />
      </geometry>
      <material
        name="">
        <color
          rgba="1 1 0 1" />
      </material>
    </visual>
    <collision>
      <origin
        xyz="0 0 0"
        rpy="0 0 0" />
      <geometry>
        <mesh
          filename="package://car_robot/meshes/front-left-hinge.STL" />
      </geometry>
    </collision>
  </link>
  <joint
    name="fl-hinge"
    type="revolute">
    <origin
      xyz="0.254 0.1397 0.0608"
      rpy="0 0 0" />
    <parent
      link="base_link" />
    <child
      link="front-left-hinge" />
    <axis
      xyz="0 0 -1" />
    <limit
      lower="-1"
      upper="1"
      effort="0"
      velocity="0" />
  </joint>
  <link
    name="front-left-wheel">
    <inertial>
      <origin
        xyz="-0.000542238634311243 -2.77555756156289E-17 -0.0380961412384963"
        rpy="0 0 0" />
      <mass
        value="2.43249992415545" />
      <inertia
        ixx="0.00755355776923952"
        ixy="1.88640504073853E-18"
        ixz="7.39771592248954E-05"
        iyy="0.00755250482076537"
        iyz="1.95246869510358E-18"
        izz="0.0127499292164544" />
    </inertial>
    <visual>
      <origin
        xyz="0 0 0"
        rpy="0 0 0" />
      <geometry>
        <mesh
          filename="package://car_robot/meshes/front-left-wheel.STL" />
      </geometry>
      <material
        name="">
        <color
          rgba="0 0 0 1" />
      </material>
    </visual>
    <collision>
      <origin
        xyz="0 0 0"
        rpy="0 0 0" />
      <geometry>
        <mesh
          filename="package://car_robot/meshes/front-left-wheel.STL" />
      </geometry>
    </collision>
  </link>
  <joint
    name="fl-wheel"
    type="continuous">
    <origin
      xyz="-0.000542238634311021 0.0380961412384964 -0.2005"
      rpy="1.5707963267949 0 -3.14159265358979" />
    <parent
      link="front-left-hinge" />
    <child
      link="front-left-wheel" />
    <axis
      xyz="-0.0142319851525261 0 -0.999898720170507" />
  </joint>
  <link
    name="front-right-hinge">
    <inertial>
      <origin
        xyz="-5.55111512312578E-17 0 -0.118799628145585"
        rpy="0 0 0" />
      <mass
        value="0.633612488698205" />
      <inertia
        ixx="0.00421634076613872"
        ixy="3.80852095203233E-19"
        ixz="-2.1435307693139E-21"
        iyy="0.00245975887674748"
        iyz="-1.06880068014722E-18"
        izz="0.00202629416547586" />
    </inertial>
    <visual>
      <origin
        xyz="0 0 0"
        rpy="0 0 0" />
      <geometry>
        <mesh
          filename="package://car_robot/meshes/front-right-hinge.STL" />
      </geometry>
      <material
        name="">
        <color
          rgba="1 1 0 1" />
      </material>
    </visual>
    <collision>
      <origin
        xyz="0 0 0"
        rpy="0 0 0" />
      <geometry>
        <mesh
          filename="package://car_robot/meshes/front-right-hinge.STL" />
      </geometry>
    </collision>
  </link>
  <joint
    name="fr-hinge"
    type="revolute">
    <origin
      xyz="0.254 -0.1397 0.0608"
      rpy="0 0 0" />
    <parent
      link="base_link" />
    <child
      link="front-right-hinge" />
    <axis
      xyz="0 0 -1" />
    <limit
      lower="-1"
      upper="1"
      effort="0"
      velocity="0" />
  </joint>
  <link
    name="front-right-wheel">
    <inertial>
      <origin
        xyz="-5.55111512312578E-17 2.77555756156289E-17 -0.0381"
        rpy="0 0 0" />
      <mass
        value="2.43249992415545" />
      <inertia
        ixx="0.00755250482076537"
        ixy="6.00508507818468E-19"
        ixz="8.35496005193151E-19"
        iyy="0.00755250482076537"
        iyz="-3.98615026528919E-18"
        izz="0.0127509821649285" />
    </inertial>
    <visual>
      <origin
        xyz="0 0 0"
        rpy="0 0 0" />
      <geometry>
        <mesh
          filename="package://car_robot/meshes/front-right-wheel.STL" />
      </geometry>
      <material
        name="">
        <color
          rgba="0 0 0 1" />
      </material>
    </visual>
    <collision>
      <origin
        xyz="0 0 0"
        rpy="0 0 0" />
      <geometry>
        <mesh
          filename="package://car_robot/meshes/front-right-wheel.STL" />
      </geometry>
    </collision>
  </link>
  <joint
    name="fr-wheel"
    type="continuous">
    <origin
      xyz="0 -0.0381 -0.2005"
      rpy="1.5707963267949 0 0" />
    <parent
      link="front-right-hinge" />
    <child
      link="front-right-wheel" />
    <axis
      xyz="0 0 -1" />
  </joint>
  <link
    name="rear-left-wheel">
    <inertial>
      <origin
        xyz="0 0 -0.0381"
        rpy="0 0 0" />
      <mass
        value="2.43249992415545" />
      <inertia
        ixx="0.00755250482076536"
        ixy="-8.23812994843201E-19"
        ixz="-1.50602458021814E-19"
        iyy="0.00755250482076536"
        iyz="2.88296133927474E-19"
        izz="0.0127509821649285" />
    </inertial>
    <visual>
      <origin
        xyz="0 0 0"
        rpy="0 0 0" />
      <geometry>
        <mesh
          filename="package://car_robot/meshes/rear-left-wheel.STL" />
      </geometry>
      <material
        name="">
        <color
          rgba="0 0 0 1" />
      </material>
    </visual>
    <collision>
      <origin
        xyz="0 0 0"
        rpy="0 0 0" />
      <geometry>
        <mesh
          filename="package://car_robot/meshes/rear-left-wheel.STL" />
      </geometry>
    </collision>
  </link>
  <joint
    name="rl-wheel"
    type="continuous">
    <origin
      xyz="-0.254 0.1778 -0.1397"
      rpy="1.5708 0 3.1416" />
    <parent
      link="base_link" />
    <child
      link="rear-left-wheel" />
    <axis
      xyz="0 0 -1" />
  </joint>
  <link
    name="rear-right-wheel">
    <inertial>
      <origin
        xyz="0 0 -0.0381"
        rpy="0 0 0" />
      <mass
        value="2.43249992415545" />
      <inertia
        ixx="0.00755250482076537"
        ixy="1.16151947225978E-18"
        ixz="3.90126123152596E-19"
        iyy="0.00755250482076537"
        iyz="7.17453761935092E-19"
        izz="0.0127509821649285" />
    </inertial>
    <visual>
      <origin
        xyz="0 0 0"
        rpy="0 0 0" />
      <geometry>
        <mesh
          filename="package://car_robot/meshes/rear-right-wheel.STL" />
      </geometry>
      <material
        name="">
        <color
          rgba="0 0 0 1" />
      </material>
    </visual>
    <collision>
      <origin
        xyz="0 0 0"
        rpy="0 0 0" />
      <geometry>
        <mesh
          filename="package://car_robot/meshes/rear-right-wheel.STL" />
      </geometry>
    </collision>
  </link>
  <joint
    name="rr-wheel"
    type="continuous">
    <origin
      xyz="-0.254 -0.1778 -0.1397"
      rpy="1.5708 0 0" />
    <parent
      link="base_link" />
    <child
      link="rear-right-wheel" />
    <axis
      xyz="0 0 -1" />
  </joint>
  <link
    name="Lidar">
    <inertial>
      <origin
        xyz="5.55111512312578E-17 -1.60727870924178E-18 -0.0127"
        rpy="0 0 0" />
      <mass
        value="0.0128703699690764" />
      <inertia
        ixx="1.21091948384887E-06"
        ixy="-5.87747175411144E-39"
        ixz="4.01153705072005E-39"
        iyy="1.21091948384887E-06"
        iyz="-7.78263594347942E-38"
        izz="1.03793098615617E-06" />
    </inertial>
    <visual>
      <origin
        xyz="0 0 0"
        rpy="0 0 0" />
      <geometry>
        <mesh
          filename="package://car_robot/meshes/Lidar.STL" />
      </geometry>
      <material
        name="">
        <color
          rgba="0 0 0 1" />
      </material>
    </visual>
    <collision>
      <origin
        xyz="0 0 0"
        rpy="0 0 0" />
      <geometry>
        <mesh
          filename="package://car_robot/meshes/Lidar.STL" />
      </geometry>
    </collision>
  </link>
  <joint
    name="laser"
    type="fixed">
    <origin
      xyz="0.45 0 0.2262"
      rpy="0 0 0" />
    <parent
      link="base_link" />
    <child
      link="Lidar" />
    <axis
      xyz="0 0 0" />
  </joint>
     <ros2_control name="GazeboSystem" type="system">
 <hardware>
     <plugin>gazebo_ros2_control/GazeboSystem</plugin>
 </hardware>
 # Velocity Controllers

 <joint name="rr-wheel">
     <command_interface name="velocity">
         <param name="min">-1000.0</param>
         <param name="max">1000.0</param>
     </command_interface>
     <state_interface name="position"/>
     <state_interface name="velocity"/>
 </joint>
 <joint name="rl-wheel">
     <command_interface name="velocity">
         <param name="min">-1000.0</param>
         <param name="max">1000.0</param>
     </command_interface>
     <state_interface name="position"/>
     <state_interface name="velocity"/>
 </joint>
  <joint name="fr-wheel">
     <command_interface name="velocity">
         <param name="min">-1000.0</param>
         <param name="max">1000.0</param>
     </command_interface>
     <state_interface name="position"/>
     <state_interface name="velocity"/>
 </joint>
  <joint name="fl-wheel">
     <command_interface name="velocity">
         <param name="min">-1000.0</param>
         <param name="max">1000.0</param>
     </command_interface>
     <state_interface name="position"/>
     <state_interface name="velocity"/>
 </joint>
# Position Controller
 <joint name="fl-hinge">
     <command_interface name="position">
         <param name="min">-3.14</param>
         <param name="max">3.14</param>
     </command_interface>
     <state_interface name="position"/>
     <state_interface name="velocity"/>
 </joint>
 <joint name="fr-hinge">
     <command_interface name="position">
         <param name="min">-3.14</param>
         <param name="max">3.14</param>
     </command_interface>
     <state_interface name="position"/>
     <state_interface name="velocity"/>
 </joint>
 </ros2_control>
<gazebo>
    <plugin filename="libgazebo_ros2_control.so" name="gazebo_ros2_control">
        <parameters>$(find car_robot)/config/control.yaml</parameters>
    </plugin>
</gazebo> 
<gazebo reference="Lidar">
  <sensor name="lidar" type="ray">
    <pose>0.0 0.0 0.0 0 0 0</pose>
    <always_on>true</always_on>
    <visualize>true</visualize>
    <update_rate>5</update_rate>
    <ray>
      <scan>
        <horizontal>
          <samples>360</samples>
          <resolution>1.00000</resolution>
          <min_angle>0.000000</min_angle>
          <max_angle>6.280000</max_angle>
        </horizontal>
      </scan>
      <range>
        <min>0.120000</min>
        <max>3.5</max>
        <resolution>0.015000</resolution>
      </range>
      <noise>
        <type>gaussian</type>
        <mean>0.0</mean>
        <stddev>0.01</stddev>
      </noise>
    </ray>
    <plugin name="scan" filename="libgazebo_ros_ray_sensor.so">
      <ros>
        <remapping>~/out:=scan</remapping>
      </ros>
      <output_type>sensor_msgs/LaserScan</output_type>
      <frame_name>Lidar</frame_name>
    </plugin>
  </sensor>
  </gazebo>
  #IMU
  <gazebo reference="base_link">
  <gravity>true</gravity>
  <sensor name="imu_sensor" type="imu">
    <always_on>true</always_on>
    <update_rate>100</update_rate>
    <visualize>true</visualize>
    <topic>__default_topic__</topic>
    <plugin filename="libgazebo_ros_imu_sensor.so" name="imu_plugin">
      <topicName>imu</topicName>
      <bodyName>base_link</bodyName>
      <updateRateHZ>10.0</updateRateHZ>
      <gaussianNoise>0.0</gaussianNoise>
      <xyzOffset>0 0 0</xyzOffset>
      <rpyOffset>0 0 0</rpyOffset>
      <frameName>base_link</frameName>
      <initialOrientationAsReference>false</initialOrientationAsReference>
    </plugin>
    <pose>0 0 0 0 0 0</pose>
  </sensor>
</gazebo>
</robot>